try {
  console.log(a);
  let a = 3;
}
catch(err) {
    console.log('let перед использованием нужно объявить!'); 
}
